.
----------------------------------------------------------------------
Ran 1 test in 1.773s

OK
...F.FF
======================================================================
FAIL: test_special_characters (rnvs_tb.blocks.block2.QOTDClientTestCase)
Test clients ability to correctly output nullbytes to stdout.
----------------------------------------------------------------------
Traceback (most recent call last):
  File "/usr/local/lib/python3.6/dist-packages/rnvs_tb/common.py", line 32, in log_wrapper
    return fun(*args, **kwargs)
  File "/usr/local/lib/python3.6/dist-packages/rnvs_tb/blocks/block2.py", line 405, in test_special_characters
    self.assertIsNotNone(pattern.fullmatch(out), msg=f'Client returned quote that does not match: {out}')
AssertionError: unexpectedly None : Client returned quote that does not match: bytearray(b'This quote contains a \n as well as  byte!')

======================================================================
FAIL: test_null_characters (rnvs_tb.blocks.block2.QOTDServerTestCase)
Test the servers handling of special characters like a null byte.
----------------------------------------------------------------------
Traceback (most recent call last):
  File "/usr/local/lib/python3.6/dist-packages/rnvs_tb/common.py", line 32, in log_wrapper
    return fun(*args, **kwargs)
  File "/usr/local/lib/python3.6/dist-packages/rnvs_tb/blocks/block2.py", line 169, in test_null_characters
    msg='No response from server received in time!')
AssertionError: False is not true : No response from server received in time!

======================================================================
FAIL: test_one_line (rnvs_tb.blocks.block2.QOTDServerTestCase)
Test the servers ability to serve a simple quote from a file, while accepting extra newline and null bytes.
----------------------------------------------------------------------
Traceback (most recent call last):
  File "/usr/local/lib/python3.6/dist-packages/rnvs_tb/common.py", line 32, in log_wrapper
    return fun(*args, **kwargs)
  File "/usr/local/lib/python3.6/dist-packages/rnvs_tb/blocks/block2.py", line 105, in test_one_line
    self.assertTrue(ready, msg=f'Server did not open port 17 within {self.startupTimeout} seconds after starting')
AssertionError: False is not true : Server did not open port 17 within 3.0 seconds after starting

----------------------------------------------------------------------
Ran 7 tests in 21.755s

FAILED (failures=3)
