.
----------------------------------------------------------------------
Ran 1 test in 1.768s

OK
FFFFFFF
======================================================================
FAIL: test_basic (rnvs_tb.blocks.block2.QOTDClientTestCase)
Test clients ability to return a simple quote with no special cases except for a newline.
----------------------------------------------------------------------
Traceback (most recent call last):
  File "/usr/local/lib/python3.6/dist-packages/rnvs_tb/common.py", line 32, in log_wrapper
    return fun(*args, **kwargs)
  File "/usr/local/lib/python3.6/dist-packages/rnvs_tb/blocks/block2.py", line 307, in test_basic
    self.assertIsNotNone(pattern.fullmatch(out), msg=f'Client returned quote in unacceptable form: {out}')
AssertionError: unexpectedly None : Client returned quote in unacceptable form: bytearray(b"client: connecting to 172.18.0.3\nclient: received: \'Lorem Ipsum dolor sit amet\n\'")

======================================================================
FAIL: test_basic_but_exact (rnvs_tb.blocks.block2.QOTDClientTestCase)
Essentially the same test as test_basic but with exact string matching of the quote.
----------------------------------------------------------------------
Traceback (most recent call last):
  File "/usr/local/lib/python3.6/dist-packages/rnvs_tb/common.py", line 32, in log_wrapper
    return fun(*args, **kwargs)
  File "/usr/local/lib/python3.6/dist-packages/rnvs_tb/blocks/block2.py", line 328, in test_basic_but_exact
    self.assertIsNotNone(pattern.fullmatch(out), msg=f'Client returned quote that does not match: {out}')
AssertionError: unexpectedly None : Client returned quote that does not match: bytearray(b"client: connecting to 172.18.0.3\nclient: received: \'Lorem Ipsum dolor sit amet\n\'")

======================================================================
FAIL: test_long_quote (rnvs_tb.blocks.block2.QOTDClientTestCase)
Test clients ability to retrieve an overly long quote.
----------------------------------------------------------------------
Traceback (most recent call last):
  File "/usr/local/lib/python3.6/dist-packages/rnvs_tb/common.py", line 32, in log_wrapper
    return fun(*args, **kwargs)
  File "/usr/local/lib/python3.6/dist-packages/rnvs_tb/blocks/block2.py", line 365, in test_long_quote
    self.assertEqual(quote, out, msg='Stdout differs from sent quote!')
AssertionError: b'Lorem Ipsum dolor sit amet\nLorem Ipsum [4212 chars]et\n' != bytearray(b"client: connecting to 172.18.0[4279 chars]n\'") : Stdout differs from sent quote!

======================================================================
FAIL: test_special_characters (rnvs_tb.blocks.block2.QOTDClientTestCase)
Test clients ability to correctly output nullbytes to stdout.
----------------------------------------------------------------------
Traceback (most recent call last):
  File "/usr/local/lib/python3.6/dist-packages/rnvs_tb/common.py", line 32, in log_wrapper
    return fun(*args, **kwargs)
  File "/usr/local/lib/python3.6/dist-packages/rnvs_tb/blocks/block2.py", line 405, in test_special_characters
    self.assertIsNotNone(pattern.fullmatch(out), msg=f'Client returned quote that does not match: {out}')
AssertionError: unexpectedly None : Client returned quote that does not match: bytearray(b"client: connecting to 172.18.0.3\nclient: received: \'This quote contains a \n as well as \'")

======================================================================
FAIL: test_long_quote (rnvs_tb.blocks.block2.QOTDServerTestCase)
Test the servers handling of arbitrarily long quotes.
----------------------------------------------------------------------
Traceback (most recent call last):
  File "/usr/local/lib/python3.6/dist-packages/rnvs_tb/common.py", line 32, in log_wrapper
    return fun(*args, **kwargs)
  File "/usr/local/lib/python3.6/dist-packages/rnvs_tb/blocks/block2.py", line 210, in test_long_quote
    self.assertTrue(ready, msg=f'Server did not open port 17 within {self.startupTimeout} seconds after starting')
AssertionError: False is not true : Server did not open port 17 within 3.0 seconds after starting

======================================================================
FAIL: test_null_characters (rnvs_tb.blocks.block2.QOTDServerTestCase)
Test the servers handling of special characters like a null byte.
----------------------------------------------------------------------
Traceback (most recent call last):
  File "/usr/local/lib/python3.6/dist-packages/rnvs_tb/common.py", line 32, in log_wrapper
    return fun(*args, **kwargs)
  File "/usr/local/lib/python3.6/dist-packages/rnvs_tb/blocks/block2.py", line 160, in test_null_characters
    self.assertTrue(ready, msg=f'Server did not open port 17 within {self.startupTimeout} seconds after starting')
AssertionError: False is not true : Server did not open port 17 within 3.0 seconds after starting

======================================================================
FAIL: test_one_line (rnvs_tb.blocks.block2.QOTDServerTestCase)
Test the servers ability to serve a simple quote from a file, while accepting extra newline and null bytes.
----------------------------------------------------------------------
Traceback (most recent call last):
  File "/usr/local/lib/python3.6/dist-packages/rnvs_tb/common.py", line 32, in log_wrapper
    return fun(*args, **kwargs)
  File "/usr/local/lib/python3.6/dist-packages/rnvs_tb/blocks/block2.py", line 105, in test_one_line
    self.assertTrue(ready, msg=f'Server did not open port 17 within {self.startupTimeout} seconds after starting')
AssertionError: False is not true : Server did not open port 17 within 3.0 seconds after starting

----------------------------------------------------------------------
Ran 7 tests in 24.149s

FAILED (failures=7)
