.
----------------------------------------------------------------------
Ran 1 test in 1.679s

OK
...FFF.
======================================================================
FAIL: test_special_characters (rnvs_tb.blocks.block2.QOTDClientTestCase)
Test clients ability to correctly output nullbytes to stdout.
----------------------------------------------------------------------
Traceback (most recent call last):
  File "/usr/local/lib/python3.6/dist-packages/rnvs_tb/common.py", line 32, in log_wrapper
    return fun(*args, **kwargs)
  File "/usr/local/lib/python3.6/dist-packages/rnvs_tb/blocks/block2.py", line 405, in test_special_characters
    self.assertIsNotNone(pattern.fullmatch(out), msg=f'Client returned quote that does not match: {out}')
AssertionError: unexpectedly None : Client returned quote that does not match: bytearray(b'This quote contains a \n as well as ')

======================================================================
FAIL: test_long_quote (rnvs_tb.blocks.block2.QOTDServerTestCase)
Test the servers handling of arbitrarily long quotes.
----------------------------------------------------------------------
Traceback (most recent call last):
  File "/usr/local/lib/python3.6/dist-packages/rnvs_tb/common.py", line 32, in log_wrapper
    return fun(*args, **kwargs)
  File "/usr/local/lib/python3.6/dist-packages/rnvs_tb/blocks/block2.py", line 215, in test_long_quote
    self.assertTrue(connected, msg='Client could not connect to server!')
AssertionError: False is not true : Client could not connect to server!

======================================================================
FAIL: test_null_characters (rnvs_tb.blocks.block2.QOTDServerTestCase)
Test the servers handling of special characters like a null byte.
----------------------------------------------------------------------
Traceback (most recent call last):
  File "/usr/local/lib/python3.6/dist-packages/rnvs_tb/common.py", line 32, in log_wrapper
    return fun(*args, **kwargs)
  File "/usr/local/lib/python3.6/dist-packages/rnvs_tb/blocks/block2.py", line 172, in test_null_characters
    msg='Server returned incorrect quote ({})!'.format(self.reply))
AssertionError: unexpectedly None : Server returned incorrect quote (b'This quote contains a ')!

----------------------------------------------------------------------
Ran 7 tests in 18.565s

FAILED (failures=3)
